[Thu, 02 Jan 20 16:45:02 +0000][ERROR] {"message":"Response was already sent","trace":"#0 \/var\/www\/html\/app\/plugins\/SecurityPlugin.php(96): Phalcon\\Http\\Response->send()\n#1 [internal function]: SecurityPlugin->beforeException(Object(Phalcon\\Events\\Event), Object(Phalcon\\Mvc\\Dispatcher), Object(Phalcon\\Http\\Response\\Exception))\n#2 [internal function]: Phalcon\\Events\\Manager->fireQueue(Array, Object(Phalcon\\Events\\Event))\n#3 [internal function]: Phalcon\\Events\\Manager->fire('dispatch:before...', Object(Phalcon\\Mvc\\Dispatcher), Object(Phalcon\\Http\\Response\\Exception))\n#4 [internal function]: Phalcon\\Mvc\\Dispatcher->_handleException(Object(Phalcon\\Http\\Response\\Exception))\n#5 [internal function]: Phalcon\\Dispatcher->dispatch()\n#6 \/var\/www\/html\/public\/index.php(42): Phalcon\\Mvc\\Application->handle()\n#7 {main}"}
[Thu, 02 Jan 20 16:45:07 +0000][ERROR] {"message":"ApiBackEndController handler class cannot be loaded","trace":"#0 [internal function]: Phalcon\\Mvc\\Dispatcher->_throwDispatchException('ApiBackEndContr...', 2)\n#1 [internal function]: Phalcon\\Dispatcher->dispatch()\n#2 \/var\/www\/html\/public\/index.php(42): Phalcon\\Mvc\\Application->handle()\n#3 {main}"}
[Thu, 02 Jan 20 16:45:07 +0000][ERROR] {"message":"SQLSTATE[08006] [7] FATAL:  could not open relation mapping file \"global\/pg_filenode.map\": No such file or directory","trace":"#0 [internal function]: PDO->__construct('pgsql:host=phal...', 'postgres', 'root', Array)\n#1 [internal function]: Phalcon\\Db\\Adapter\\Pdo->connect(Array)\n#2 [internal function]: Phalcon\\Db\\Adapter\\Pdo\\Postgresql->connect(Array)\n#3 \/var\/www\/html\/app\/config\/services.php(76): Phalcon\\Db\\Adapter\\Pdo->__construct(Array)\n#4 [internal function]: Closure->{closure}()\n#5 [internal function]: Phalcon\\Di\\Service->resolve(NULL, Object(Phalcon\\Di\\FactoryDefault))\n#6 [internal function]: Phalcon\\Di->get('db', NULL)\n#7 [internal function]: Phalcon\\Di->getShared('db')\n#8 [internal function]: Phalcon\\Mvc\\Model\\Manager->_getConnection(Object(HelloWorld\\Models\\Utilisateurs), NULL)\n#9 [internal function]: Phalcon\\Mvc\\Model\\Manager->getReadConnection(Object(HelloWorld\\Models\\Utilisateurs))\n#10 [internal function]: Phalcon\\Mvc\\Model->getReadConnection()\n#11 [internal function]: Phalcon\\Mvc\\Model\\MetaData\\Strategy\\Introspection->getMetaData(Object(HelloWorld\\Models\\Utilisateurs), Object(Phalcon\\Di\\FactoryDefault))\n#12 [internal function]: Phalcon\\Mvc\\Model\\MetaData->_initialize(Object(HelloWorld\\Models\\Utilisateurs), 'helloworld\\\\mode...', 'utilisateurs', 'public')\n#13 [internal function]: Phalcon\\Mvc\\Model\\MetaData->readMetaDataIndex(Object(HelloWorld\\Models\\Utilisateurs), 4)\n#14 [internal function]: Phalcon\\Mvc\\Model\\MetaData->getDataTypes(Object(HelloWorld\\Models\\Utilisateurs))\n#15 [internal function]: Phalcon\\Mvc\\Model::_invokeFinder('findById', Array)\n#16 \/var\/www\/html\/app\/controllers\/UtilisateursController.php(23): Phalcon\\Mvc\\Model::__callStatic('findById', Array)\n#17 [internal function]: UtilisateursController->infoUtilisateurAction('3')\n#18 [internal function]: Phalcon\\Dispatcher->callActionMethod(Object(UtilisateursController), 'infoUtilisateur...', Array)\n#19 [internal function]: Phalcon\\Dispatcher->dispatch()\n#20 \/var\/www\/html\/public\/index.php(42): Phalcon\\Mvc\\Application->handle()\n#21 {main}"}
[Thu, 02 Jan 20 16:46:29 +0000][ERROR] {"message":"Response was already sent","trace":"#0 \/var\/www\/html\/app\/plugins\/SecurityPlugin.php(96): Phalcon\\Http\\Response->send()\n#1 [internal function]: SecurityPlugin->beforeException(Object(Phalcon\\Events\\Event), Object(Phalcon\\Mvc\\Dispatcher), Object(Phalcon\\Http\\Response\\Exception))\n#2 [internal function]: Phalcon\\Events\\Manager->fireQueue(Array, Object(Phalcon\\Events\\Event))\n#3 [internal function]: Phalcon\\Events\\Manager->fire('dispatch:before...', Object(Phalcon\\Mvc\\Dispatcher), Object(Phalcon\\Http\\Response\\Exception))\n#4 [internal function]: Phalcon\\Mvc\\Dispatcher->_handleException(Object(Phalcon\\Http\\Response\\Exception))\n#5 [internal function]: Phalcon\\Dispatcher->dispatch()\n#6 \/var\/www\/html\/public\/index.php(42): Phalcon\\Mvc\\Application->handle()\n#7 {main}"}
[Thu, 02 Jan 20 16:46:32 +0000][ERROR] {"message":"ApiBackEndController handler class cannot be loaded","trace":"#0 [internal function]: Phalcon\\Mvc\\Dispatcher->_throwDispatchException('ApiBackEndContr...', 2)\n#1 [internal function]: Phalcon\\Dispatcher->dispatch()\n#2 \/var\/www\/html\/public\/index.php(42): Phalcon\\Mvc\\Application->handle()\n#3 {main}"}
[Thu, 02 Jan 20 16:47:24 +0000][ERROR] {"message":"SQLSTATE[23505]: Unique violation: 7 ERROR:  duplicate key value violates unique constraint \"utilisateurs_un\"\nDETAIL:  Key (email)=(conor.doe@les-enovateurs.com) already exists.","trace":"#0 [internal function]: PDOStatement->execute()\n#1 [internal function]: Phalcon\\Db\\Adapter\\Pdo->executePrepared(Object(PDOStatement), Array, Array)\n#2 [internal function]: Phalcon\\Db\\Adapter\\Pdo->execute('INSERT INTO \"pu...', Array, Array)\n#3 [internal function]: Phalcon\\Db\\Adapter->insert(Array, Array, Array, Array)\n#4 [internal function]: Phalcon\\Mvc\\Model->_doLowInsert(Object(Phalcon\\Mvc\\Model\\MetaData\\Memory), Object(Phalcon\\Db\\Adapter\\Pdo\\Postgresql), Array, 'id')\n#5 \/var\/www\/html\/app\/controllers\/UtilisateursController.php(42): Phalcon\\Mvc\\Model->save(Array)\n#6 [internal function]: UtilisateursController->nouvelAction()\n#7 [internal function]: Phalcon\\Dispatcher->callActionMethod(Object(UtilisateursController), 'nouvelAction', Array)\n#8 [internal function]: Phalcon\\Dispatcher->dispatch()\n#9 \/var\/www\/html\/public\/index.php(42): Phalcon\\Mvc\\Application->handle()\n#10 {main}"}
